Workbook
Name _PP1: #REF!
Name _PP2: #REF!
Name _PP3: #REF!
Name _PP4: #REF!
Name _SB1: #REF!
Name _SB2: #REF!
Name _SB3: #REF!
Name _SB4: #REF!
Name AddPage: #REF!
Name btnCls_Click: #REF!
Name btnOk_Click: #REF!
Name BytecountMain: #REF!
Name cal_index_size: #REF!
Name cal_table_size: #REF!
Name ChCHECK1: #REF!
Name ChCHECK2: #REF!
Name cmdWho_Click: #REF!
Name CULC.cal_index_size: #REF!
Name DEL: #REF!
Name Dialog_Show: #REF!
Name edtAuthor_Change: #REF!
Name edtSaetu_Change: #REF!
Name edtSyonin_Change: #REF!
Name Endmsg2: #REF!
Name Endmsg3: #REF!
Name ＪＪ: #REF!
Name KAKOMU1: #REF!
Name KAKOMU2: #REF!
Name ＫＫＫ: #REF!
Name main: #REF!
Name main2: #REF!
Name modAbout.Dialog_Show: #REF!
Name Module1.SEL_DEL: #REF!
Name NowDate: #REF!
Name OptCHECK1: #REF!
Name OptCHECK2: #REF!
Name PRICELST: #REF!
Name printera3: #REF!
Name PRINTERA4: #REF!
Name printerA4yoko: #REF!
Name prmouta: #REF!
Name prmoutall: #REF!
Name prmoutb: #REF!
Name prmoutc: #REF!
Name prmoutd: #REF!
Name prmoute: #REF!
Name prmoutf: #REF!
Name prmoutg: #REF!
Name prmouth: #REF!
Name prmouti: #REF!
Name prmoutj: #REF!
Name prmoutk: #REF!
Name prmoutl: #REF!
Name prmoutm: #REF!
Name prmoutn: #REF!
Name prmouto: #REF!
Name prmoutp: #REF!
Name prmoutq: #REF!
Name prmoutr: #REF!
Name prmouts: #REF!

Sheet 表紙
B2: =MID(CELL("filename",$A$1),FIND("[",CELL("filename",$A$1))+1,FIND("]",CELL("filename",$A$1))-FIND("[",CELL("filename",$A$1))-1-LEN(".xls")) -> 21基本_MS盤_03_SCB、POM基本設計書_v1.4_R01_20240703_work. | I2: SCB/POMサーバ基本設計書（AEP基盤編）
L16: 承認 | P16: 作成
P17: 44566
P18: MSYS

Sheet 更新履歴
A1: SCB/POMサーバ基本設計書（AEP基盤編） 更新履歴
A3: 契約番号 | I3: - | AD3: システム名 | AM3: コールセンターシステム | BR3: 承認者 | BY3: 作成者 | CA3: MSYS
A4: プロジェクト名 | I4: CC改革2.0 | AD4: サブシステム名 | AM4: SMCC-IVR
AD5: 作成日 | AO5: 改定日 | AZ5: 承認日 | BK5: 版数 | BN5: 1.4
B8: Ver. | I8: 改定年月日 | R8: 改定概要 | BT8: 改定者
B10: 1.0 | I10: 2022/1/5 | R10: 初版 | BT10: MSYS
B12: 1.1 | I12: 2022/4/7 | R12: ・JRI様修正分（ネットワークフィルタリングに関する記載）の反映（4-2） ・ポート番号修正（4-2-2 ⑧） ・監視等の通信経路を追加（4-2-2） ・監視等の通信の暗号化の記載を追加（8-2-1） ・時刻同期通信の通信経路を追加（4-2-2） ・SNMPトラップ送信の通信経路を追加（4-2-2） | BT12: MSYS
B13: 1.2 | I13: 2022/8/31 | R13: ・「OP空き情報取得」による通信を非暗号化に修正（8-2-1 通信の暗号化 ⑩） | BT13: MSYS
B14: 1.3 | I14: 2022/10/25 | R14: ・POMメンテナンス機能を追加（6-3.POM機能設計 (ﾒﾝﾃ)） | BT14: MSYS
B15: 1.4 | I15: 2024/7/3 | R15: 6-3-7. ジョブスケジュールに「POMサービス起動状態チェック」を追加 6-3-4. ログローテションに「POMサービス起動状態チェック」での出力ログファイルを追加 | BT15: MSYS

Sheet 目次
A1: SCM/POMサーバ基本設計書（AEP基盤編） 目次
A3: 契約番号 | I3: - | AD3: システム名 | AM3: コールセンターシステム | BR3: 承認者 | BY3: 作成者 | CA3: MSYS
A4: プロジェクト名 | I4: CC改革2.0 | AD4: サブシステム名 | AM4: SMCC-IVR
AD5: 作成日 | AH5: 44556 | AO5: 改定日 | AZ5: 承認日 | BK5: 版数 | BN5: 1
F11: 1.システム概要 | V11: 1-1.システム導入の目的 | AV11: 8.セキュリティ設計 | BL11: 8-1.ID設計（ユーザ管理）
V12: 1-2.システム全体構成 | BL12: 8-2.暗号化
BM13: 8-2-1 通信の暗号化
F14: 2. 構成概要 | V14: 2-1.SCB、POM、POMDB | BM14: 8-2-2 保持データの暗号化
W15: 2-1-1.SCB、POM システム構築範囲 | BL15: 8-3. アクセスコントロール
W16: 2-1-2.SCB、POM、POMDB 設計・構築対象製品 | BL16: 8-4.セキュリティパッチ適用
BL17: 8-5.ネットワークフィルタリング
F18: 3.HW SW構成 | V18: 3‐1 仮想サーバレイアウト
V19: 3-2.HW構成 | AV19: 9.ミドルウェアキャパシティ設計 | BL19: 9-1.基礎数値
W20: 3-2-1. Avaya社の推奨環境 | BL20: 9-2.ライセンス
W21: 3-2-2.担保すべき業務量 | BL21: 9-3.システム上限数量
W22: 3-2-3.HW構成内容（必要スペック）
V23: 3-3.SW構成 | AV23: 10.障害対策設計 | BL23: 10-1.障害対策方針
W24: 3-3-1. サーバ | BL24: 10-2.障害時の影響とその対策
W25: 3-3-2. 端末 | BM25: 10-2-1 サーバ障害
BM26: 10-2-2 ブレード障害
F27: 4.NW構成 | V27: 4-1.NWセグメント構成
W28: 4-1-1.NWセグメントについて | AV28: 11.運用設計
V29: 4-2.ネットワーク論理構成
W30: 4-2-1.ネットワーク論理構成図 | AV30: 12.ホスト名ネーミングルール
W31: 4-2-2.ネットワーク帯域
W32: 4-2-3.ネットワークフィルタリング | AV32: 13.バックアップサーバ設計
F34: 5.SCB機能設計 | V34: 5-1. 全体概要 | AV34: 14.時刻同期設計
V35: 5-2. 業務機能
V36: 5-3. メンテナンス機能 | AV36: 15.用語集
V37: 5-4. 管理機能
F39: 6.POM機能設計 | V39: 6-1. 全体概要
V40: 6-2. 業務機能
V41: 6-3. メンテナンス機能
V42: 6-4. 管理機能
F44: 7.POMDB機能設計 | V44: 7-1. 全体概要
V45: 7-2. メンテナンス機能

Sheet 1.システム概要
A1: SCM/POMサーバ基本設計書（AEP基盤編） システム概要
A3: 契約番号 | I3: - | AD3: システム名 | AM3: コールセンターシステム | BR3: 承認者 | BY3: 作成者 | CA3: MSYS
A4: プロジェクト名 | I4: CC改革2.0 | AD4: サブシステム名 | AM4: SMCC-IVR
AD5: 作成日 | AH5: 44566 | AO5: 改定日 | AZ5: 承認日 | BK5: 版数 | BN5: 1
B9: 1.システム概要（折電受付・自動架電）
C11: 1-1.システム導入の目的
E13: 現在、コンタクトセンター業務は受電が中心となっており、
E14: 時間帯ごとの繁閑に合わせた人員配置を行うものの、効率化に限界がある状況である。
E16: 折返しによる「架電中心」へシフトすることにより、
E17: オペレーター配置の平準化・通話時間短縮が可能になることで、人員抑制を見込む。
E19: 現行のCTI基盤上に新規サーバ、及び新規アプリケーションを導入することにより、
E20: 折電受付・自動架電システムを実現する。
E22: 本ファイルでは、折電受付・自動架電システムに絞った内容の記載を行う。
C45: 1-2.システム全体概要
D46: システム全体概要については以下のとおり。
D48: [図 1-2-1 システム全体概要]
D88: [表 1-2-1 機能概要]
D89: No. | G89: 項目 | S89: 図 1-2-1 | Y89: 機能概要 | AP89: 内容
D90: 1 | G90: 折電予約の登録 | S90: ① | Y90: 折電予約 | AP90: 顧客（会員）がIVR受付フロー（折電予約）を介して折電の希望時間を指定し、折電を予約する
D91: 2 | S91: ② | Y91: 折電予約登録 | AP91: ①で予約された折電予約をSCBへ登録する
D92: 3 | S92: ③ | Y92: ｺｰﾙﾊﾞｯｸ登録 | AP92: ②のｺｰﾙﾊﾞｯｸ（折電予約）をSCB-DBへ登録する
D93: 4 | S93: ⑥ | Y93: ｺﾝﾀｸﾄﾘｽﾄ登録 | AP93: ③のｺｰﾙﾊﾞｯｸを、POMへ連携することで、ｺﾝﾀｸﾄﾘｽﾄを登録する。連携するｺﾝﾀｸﾄﾘｽﾄは初回架電、再架電の2種類存在する。本データが架電時の顧客リストとなる。
D94: 5 | G94: 架電 | S94: ⑦、⑧ | Y94: 架電制御 | AP94: POM-DBに登録されたｺﾝﾀｸﾄﾘｽﾄを参照し、架電を制御する
D95: 6 | S95: ⑨ | Y95: 架電 | AP95: ｺﾝﾀｸﾄﾘｽﾄの顧客に対して、架電する
D96: 7 | S96: ⑩ | Y96: オペレータ空き情報取得 | AP96: ⑨の架電量（発信数）を制御するため、CMSからｵﾍﾟﾚｰﾀの空き情報を取得する
D97: 8 | S97: ⑪ | Y97: IVR転送 | AP97: ⑨で顧客応答後（接続後）、IVR着信フローに転送する
D98: 9 | S98: ⑫ | Y98: ｺﾝﾀｸﾄﾘｽﾄ取得 | AP98: IVR着信フローに必要なｺﾝﾀｸﾄﾘｽﾄ（顧客情報）をPOMから取得する
D99: 10 | G99: 架電結果の反映 | S99: ⑬ | Y99: オペレータ着信 | AP99: オペレータに着信し、顧客と通話可能な状態になる
D100: 11 | S100: ⑬ | Y100: 架電結果連携 | AP100: 架電結果をSCB-DBへ連携する
D101: 12 | G101: 管理 | M101: 業務 | S101: ④、⑤ | Y101: ｺｰﾙﾊﾞｯｸ状態確認、出力 | AP101: 業務管理者が、SCB管理機能を利用し、ｺｰﾙﾊﾞｯｸ状態の確認、及びファイル出力する
D102: 13 | S102: ⑮、⑯ | Y102: ｺｰﾙﾊﾞｯｸｷｬﾝｾﾙ | AP102: 業務管理者が、ｺｰﾙﾊﾞｯｸ予約のｷｬﾝｾﾙを行う。ｺｰﾙﾊﾞｯｸｷｬﾝｾﾙ時は、ｷｬﾝｾﾙ指定したｺｰﾙﾊﾞｯｸとあわせて、POM側のｺｰﾙﾊﾞｯｸ（ｺﾝﾀｸﾄﾘｽﾄ）もｷｬﾝｾﾙする。
D103: 14 | M103: 開発・保守 | S103: ⑰ | Y103: 開発・保守（SCB） | AP103: ｼｽﾃﾑ管理者（SCB開発・保守担当者）が、SCB管理画面より開発・保守作業を行う。
D104: 15 | S104: ⑱ | Y104: 開発・保守（POM） | AP104: ｼｽﾃﾑ管理者（POM開発・保守担当者）が、POM管理画面より開発・保守作業を行う。

Sheet 2. 構成概要
A1: SCB/POMサーバ基本設計書（AEP基盤編） 構成概要
A3: 契約番号 | I3: - | AD3: システム名 | AM3: =目次!AM3 -> コールセンターシステム | BR3: 承認者 | BY3: 作成者 | CA3: MSYS
A4: プロジェクト名 | I4: =目次!I4 -> CC改革2.0 | AD4: サブシステム名 | AM4: =目次!AM4 -> SMCC-IVR
AD5: 作成日 | AH5: 44557 | AO5: 改定日 | AZ5: 承認日 | BK5: 版数 | BN5: 1
B9: 2. 構成概要
C11: 2-1.SCB、POM、POMDB
E13: 共通基盤に物理サーバを環境（本番、研修、開発）毎に1台ずつ、計3台増設する。
E14: 本番、研修、開発サーバ上にVMwareにて仮想サーバを3台ずつ、計9台構築する。
C16: 2-1-1.SCB、POM システム構築範囲
D18: 本システムの対象となる拠点を以下に示す。
D20: 拠点名 | S20: 説明
D21: 鰻谷センター | S21: SCB/POMサーバ群を共通基盤へ構築する拠点。（本番環境/研修環境）
D22: 大和センター | S22: SCB/POMサーバ群を共通基盤へ構築する拠点。（開発環境）
C47: 2-1-2.SCB、POM、POMDB 設計・構築対象製品
E48: 本システムの設計・構築対象プロダクトを以下に示す。なお、役割や選定バージョンといった各種情報は「3.HWSW構成」に記述する。
E49: 本システムの全体構成に関しては、「21基本_MS盤_01_基盤共通基本設計書（AEP基盤編）」を参照。
D51: <本番環境>
D52: 拠点名 | M52: 機器 | U52: プロダクト | AC52: 構築形態 | AM52: 構成 | BM52: 備考
D53: 鰻谷センター | M53: SCB | U53: SCB | AC53: 仮想(共通基盤) | AM53: SCB
M55: POM | U55: POM | AC55: 仮想(共通基盤) | AM55: POM
AC56: 仮想(共通基盤) | AM56: EPM
AC57: 仮想(共通基盤) | AM57: MPP
M58: POMDB | U58: SCB-DB | AC58: 仮想(共通基盤) | AM58: SCB-DB
U59: POM-DB | AC59: 仮想(共通基盤) | AM59: POM-DB
D61: <研修環境>
D62: 拠点名 | M62: 機器 | U62: プロダクト | AC62: 構築形態 | AM62: 機器名称 | BM62: 備考
D63: 鰻谷センター | M63: SCB | U63: SCB | AC63: 仮想(共通基盤) | AM63: SCB
M65: POM | U65: POM | AC65: 仮想(共通基盤) | AM65: POM
AC66: 仮想(共通基盤) | AM66: EPM
AC67: 仮想(共通基盤) | AM67: MPP
M68: POMDB | U68: SCB-DB | AC68: 仮想(共通基盤) | AM68: SCB-DB
U69: POM-DB | AC69: 仮想(共通基盤) | AM69: POM-DB
D71: <開発環境>
D72: 拠点名 | M72: 機器 | U72: プロダクト | AC72: 構築形態 | AM72: 機器名称 | BM72: 備考
D73: 大和センター | M73: SCB | U73: SCB | AC73: 仮想(共通基盤) | AM73: SCB
M75: POM | U75: POM | AC75: 仮想(共通基盤) | AM75: POM
AC76: 仮想(共通基盤) | AM76: EPM
AC77: 仮想(共通基盤) | AM77: MPP
M78: POMDB | U78: SCB-DB | AC78: 仮想(共通基盤) | AM78: SCB-DB
U79: POM-DB | AC79: 仮想(共通基盤) | AM79: POM-DB

Sheet 3.HW SW構成
A1: SCB/POMサーバ基本設計書（AEP基盤編） HW SW構成
A3: 契約番号 | I3: - | AD3: システム名 | AM3: =目次!AM3 -> コールセンターシステム | BR3: 承認者 | BY3: 作成者 | CA3: MSYS
A4: プロジェクト名 | I4: =目次!I4 -> CC改革2.0 | AD4: サブシステム名 | AM4: =目次!AM4 -> SMCC-IVR
AD5: 作成日 | AH5: 44566 | AO5: 改定日 | AZ5: 承認日 | BK5: 版数 | BN5: 1
B9: 3.HW SW構成
C11: 3‐1 仮想サーバレイアウト
E12: 下記に本システム導入に伴い、増設する各サーバレイアウト構成を示す。
E13: また、仮想機器における共通基盤機器は以下の配置方針に準拠し、設計する。
E15: ・機器への配置先はWindows共通基盤となる。※Windows共通基盤のスペックは「Windows共通基盤ガイド」を参照
E16: ・CPUコア数は機器ごと有効利用できるよう配置する。
E19: (1) 鰻谷センター仮想サーバレイアウト（本番、研修環境）
E50: (2) 大和センター仮想サーバレイアウト（開発環境）
C88: 3-2.HW構成
D90: SCB、POMの導入に伴い、導入後の予測される業務量を担保できる内容でHW構成を設計する。
D91: また、導入機器については全て仮想機器であることから、物理環境のHW構成は記載の対象外とする。
D92: 仮想機器におけるHW構成については以下の通り。
D94: 3-2-1.担保すべき業務量
F95: 必要スペックを決めるにあたって、基準値は以下の通り。（SMCC提示情報に基づく）
F97: No. | H97: 項目 | AA97: 担保すべき業務量 （平均）
F98: 1 | H98: 折電時の顧客接続率 | AA98: OP接続率：70%、PD架電応答率（留守電含む）：90%
F99: 2 | H99: 架電対応OP数 | AA99: 100人/日
F100: 3 | H100: 平均通話時間/件 | AA100: OPとの平均通話時間：475秒、PD架電時間：50秒
F101: 4 | H101: 折電予約受付数/時 | AA101: 1,344件
F102: 5 | H102: 折電を受ける日数 | AA102: 3日（当日、翌日、翌々日（※）） ※当日、翌日に空きが無い場合のみ
F103: 6 | H103: 予約データの保存期間 | AA103: 実行結果一覧：7日間 サマリレポート：180日間
D106: 3-2-2.HW構成内容（必要スペック）
E108: (1) | G108: 前提条件（システムキャパシティ 等）
F109: No. | H109: 製品 | Q109: 項目 | AF109: 値
G110: 1 | H110: SCB | Q110: ジョブ数 | AF110: 50 まで
G111: 2 | Q111: 折電予約受付数/day | AF111: 5,000件
G112: 3 | Q112: 予約データの保存期間 | AF112: 7日間（ただし、サマリーレポートについては180日間とする）
G113: 4 | H113: POM | Q113: POMジョブ登録数 | AF113: 100 まで(※)
G114: 5 | Q114: POMジョブ同時実行数 | AF114: 85 まで(※)
G115: 6 | H115: MPP | Q115: 同時発信数 | AF115: 250 コールまで
F117: ※ POMのキャパシティとしては記載のとおりとなるが、今回の構成ではSCBと組み合わせるため、本システムとしてはSCBの50がジョブの上限数となる
F120: ジョブ、キャンペーン、スキルの関連については別紙「21基本_MS盤_03_SCB・POM基本設計書_別紙①_システム動作概要図」を参照のこと
E125: (2) | G125: 必要スペック
F126: SCB、POM、POMDBの確保すべきスペック構成を以下の内容で定義する。
F127: No. | H127: 項目 | Q127: SCB | AA127: POM | AT127: POMDB | BE127: 根拠
AK128: MPP
...

Sheet 4.NW構成
A1: SCB/POMサーバ基本設計書（AEP基盤編） NW構成
A3: 契約番号 | I3: - | AD3: システム名 | AM3: =目次!AM3 -> コールセンターシステム | BR3: 承認者 | BY3: 作成者 | CA3: MSYS
A4: プロジェクト名 | I4: =目次!I4 -> CC改革2.0 | AD4: サブシステム名 | AM4: =目次!AM4 -> SMCC-IVR
AD5: 作成日 | AH5: 44566 | AO5: 改定日 | AZ5: 承認日 | BK5: 版数 | BN5: 1
B9: 4.NW構成
C10: 4-1.NWセグメントについて
D12: 本システムよる通信を行うNW種別は下記2種類となる。
D13: ・音声NW | L13: ：PBXの制御や音声パケットの通信を行う。
D14: ・データNW | L14: ：周辺システムとの連携や拠点端末との通信、運用監視を行う。
D16: NWセグメントの種別は下記の通り
D17: NW種別 | M17: 対象 | P17: セグメント | BL17: インテル共通基盤 | BU17: 接続先
P18: 名称 | AA18: 用途 | BL18: LAN種別(※1) | BU18: WAN(※2)
D19: 音声NW | M19: 〇 | P19: PBX制御音声 | AA19: ・PBXやそのコンポーネントとの音声や制御信号の通信に利用（PBXとの受架電） | BL19: 業務LAN | BU19: 音声
P21: PBX管理 | AA21: ・NTPサーバとの時刻同期 | BL21: 業務LAN
AA22: ・POM/SCB管理画面へのメンテナンスアクセス通信
AA23: ・Backup/Syslogサーバとのバックアップ通信
D24: データNW | M24: 〇 | P24: データ | AA24: ・折電受付フローとのREST通信 | BL24: 業務LAN | BU24: SMCCネットワーク
AA25: ・架電データ投入（REST通信）
AA26: ・架電結果データ取得（REST通信）
AA27: ・顧客情報連携のための通信
AA28: ・POMDBへのデータ保存、更新、参照のための通信
AA29: ・スキル毎のオペレータの空き状況取得のための通信
AA30: ・音声フローを実行するための通信
AA31: ・運用、監視を行うための通信
AA32: ・SCB管理画面への業務アクセス通信
D34: (※1)LAN種別は「業務LAN」で固定。業務LANを上記のセグメントにVLANで分割する。 | BE34: 〇：折電機能（SCB、POM）で利用する（実装する）
D35: (※2)WANは音声とデータで物理的に分離。 | BE35: ×：折電機能（SCB、POM）で利用しない（実装しない）
C49: 4-2.ネットワーク論理構成
D50: 4-2-1.ネットワーク論理構成図
E51: 本システムのネットワーク論理構成図を以下に示す。（※1）
E52: 以下は、本番環境をベースに記載しているが、研修環境、開発環境も同じ構成である。
BP59: （PBX制御音声セグメント）
BQ60: ① POM⇔G450
BP61: （PBX管理セグメント）
BQ62: ⑫ SCB⇒Backup
BQ63: ⑬ POM⇒Backup
BQ64: ⑭ POMDB⇒Backup
BP65: （データセグメント）
BQ66: ② WAS⇒SCB
BQ67: ③ SCB⇒POM
...

Sheet 5-1～5-2.SCB機能設計（全体概要・業務）
A1: SCM/POMサーバ基本設計書（AEP基盤編） SCB機能設計（全体概要・業務）
A3: 契約番号 | I3: - | AD3: システム名 | AM3: =目次!AM3 -> コールセンターシステム | BR3: 承認者 | BY3: 作成者 | CA3: MSYS
A4: プロジェクト名 | I4: =目次!I4 -> CC改革2.0 | AD4: サブシステム名 | AM4: =目次!AM4 -> SMCC-IVR
AD5: 作成日 | AH5: 44578 | AO5: 改定日 | AZ5: 承認日 | BK5: 版数 | BN5: 1
B9: 5.SCB機能設計
C11: 5-1.全体概要
E12: SCB機能のシステム全体概要については以下のとおり。
E50: [表 5-1-2 機能概要]
E51: No. | H51: 項目 | T51: 内容
E52: 1 | H52: 業務 | T52: SCBの折電予約の受付可能時間帯取得、折電予約登録、ｺﾝﾀｸﾄﾘｽﾄを連携などの業務機能を提供する。
E53: 2 | H53: メンテナンス | T53: 監視（プロセス、サーバリソース等）、ログローテーションなどのSCBサーバに関するメンテナンス機能を提供する。
E54: 3 | H54: 管理 | T54: 折電予約情報の状態確認、キャンセル指示等のSCB管理機能を提供する。 SCB管理機能はブラウザを介してアクセスする。
C92: 5-2.業務機能
D93: SCBの業務機能について以下に記載する。
E95: [表 5-2 業務機能]
E96: No. | H96: 項目 | Y96: 内容 | BI96: 備考
E97: 1 | H97: 業務 | M97: 折電予約の登録 | Y97: IVR（折電予約受付フロー）より連携された、折電予約情報をSCB-DBへ登録する。 | BI97: 機能詳細は5-2-1参照
E98: 2 | M98: ｺﾝﾀｸﾄﾘｽﾄ連携 | Y98: SCBにて架電対象となる折電予約情報を抽出、POMへ連携し、コンタクトリストへ登録する。 | BI98: 機能詳細は5-2-3参照
E99: 3 | M99: 架電結果連携 | Y99: POMにて架電した結果をSCBへ連携し、コールバックリストへ登録する。 | BI99: 機能詳細は5-2-2参照
D131: 5-2-1.ｺｰﾙﾊﾞｯｸ(折電予約)の登録
E133: 折電予約は、WASからSCBのAPIを利用することにより実現する。
E134: WAS上のIVR受付フローからのリクエストに応じて、SCBでは予約受付可能な時間帯の連携等のデータ取得、及び予約登録を行う。
E136: ■前提条件
F138: ① | G138: SCB APIの呼び出し元
G139: 折電予約の登録、及び受付可能な時間帯の連携は、IVR受付フローからのリクエストにより実行する。
F141: ② | G141: 利用するAPIについて
G142: IVR受付フローからのリクエストでは、SCBのREST APIを使用する。
F144: ③ | G144: SCBジョブで管理する時間枠の単位
G145: SCBジョブで管理する時間枠の単位は1時間とする。それに伴い受付可能な時間帯枠については１時間単位で管理するものとし、
G146: その単位で受付上限数（折電予約数）を設ける。受付上限数の設定はSCB管理機能により設定する。
F148: ④ | G148: SCBに登録するジョブ数
G149: POMに登録するキャンペーン数を固定数とすることに伴い（Avaya制約）、SCBに登録するジョブ数も固定数とする。
G150: SCBジョブ、POMキャンペーン登録数は、1：1とする。
G151: 用件、優先度を分類するために、SCBジョブ、POMキャンペーンを目的にあわせて登録する。
F153: ⑤ | G153: 折電予約の範囲
G154: 予約は当日、翌日のみならず、翌々日以降も設定することが可能とし、システム的に制限しない。
F156: ⑥ | G156: 折電予約の登録方法
G157: 折電予約はSCB APIを起動することで登録可能とし、ｵﾍﾟﾚｰﾀ、もしくは業務管理者が画面などから手動で登録することはできない。
F159: ⑦ | G159: 折電予約登録後の変更、キャンセル
G160: 折電予約はSCB管理機能にてキャンセル可能とする。詳細は「5-4-1.管理機能一覧 No.7」参照。
...

Sheet 5-3.SCB機能設計 (ﾒﾝﾃ)
A1: SCM/POMサーバ基本設計書（AEP基盤編） SCB機能設計 (ﾒﾝﾃ)
A3: 契約番号 | I3: - | AD3: システム名 | AM3: =目次!AM3 -> コールセンターシステム | BR3: 承認者 | BY3: 作成者 | CA3: MSYS
A4: プロジェクト名 | I4: =目次!I4 -> CC改革2.0 | AD4: サブシステム名 | AM4: =目次!AM4 -> SMCC-IVR
AD5: 作成日 | AH5: 44578 | AO5: 改定日 | AZ5: 承認日 | BK5: 版数 | BN5: 1
B9: 5-3.メンテナンス機能
C11: SCBのメンテナンス機能について、以下に記載する。
E13: No. | H13: 項目 | AI13: 内容 | BN13: 備考
E14: 1 | H14: メンテナンス | N14: 監視 ※1 | X14: プロセス監視 | AI14: プロセスの正常起動を定期的に監視する | BN14: 機能詳細は5-3-1-1参照
X15: アプリケーション監視 | AI15: アプリケーション正常動作を定期的に監視する | BN15: 機能詳細は5-3-1-2参照
X16: リソース監視 | AI16: CPU、メモリ、ディスク利用率を定期的に監視する | BN16: 機能詳細は5-3-1-3参照
X17: 死活監視 | AI17: 死活を定期的に監視する | BN17: 機能詳細は5-3-1-4参照
E18: 2 | N18: 定期リブート | AI18: SCBのサーバリブートを定期的に行う | BN18: 機能詳細は5-3-2参照
E19: 3 | N19: DBクリア | AI19: 不要になったSCB-DB内のデータを定期的に削除する | BN19: 機能詳細は5-3-3参照
E20: 4 | N20: ログローテーション | AI20: 時間の経過とともに容量が増加する増加率が高いログ等のデータファイルについては、ディスク容量の圧迫を回避するために、データファイル削除を定期的に行う | BN20: 機能詳細は5-3-4参照
E21: 5 | N21: バックアップ | AI21: システム（OSレイヤー）をバックアップする | BN21: 機能詳細は5-3-5参照
E22: 6 | N22: POMキャンペーン停止 | AI22: POMキャンペーンを停止する | BN22: 機能詳細は5-3-6参照
E23: 7 | N23: POMキャンペーン再起動 | AI23: POMキャンペーンを再起動する | BN23: 機能詳細は5-3-7参照
E24: 8 | N24: 処理実績収集 | AI24: ＣＰＵ/DISK使用率など、ハードウェアリソースの使用量を収集する | BN24: 機能詳細は5-3-8参照
E25: 9 | N25: ジョブスケジュール | AI25: 策定されたシステム稼動スケジュールおよびシステムメンテナンススケジュールに沿って各ジョブが起動、実行されるようにスケジュールを設定する | BN25: 機能詳細は5-3-9参照
E26: ※1 HW監視については、JRI様設計の範囲であることから記載の対象外とする。
C29: 5-3-1. 監視機能
D31: 監視機能の全体概要については以下の通り。
D32: 本項では、SCBに関する監視機能を記載する箇所だが、比較のためにPOM、POMDBもあわせて記載する。
D34: サーバ別に監視方法が異なるため、各サーバごとの監視方法を以下に記載する。
D35: 運用ルールに準拠し原則WebSAMエージェントを利用して監視を行うが、POMにおいてはAvayaOSであるため、WebSAMエージェントをインストールした場合、
D36: Avayaサポート対象外となってしまうため、運用ツール（WebSAM監視代替ツール）を利用することで監視する。
D38: ■サーバ別の監視方法
E39: No. | G39: サーバ | O39: OS | AH39: 監視方法
E40: 1 | G40: SCB | O40: Red Hat Enterprise Linux（64bit版） | AH40: WebSAMエージェントをインストールすることで監視する
E41: 2 | G41: POM | O41: Avaya Enterprise Linux（64bit版） | AH41: WebSAM監視代替ツールをデプロイすることで監視する
E42: 3 | G42: POMDB | O42: Red Hat Enterprise Linux（64bit版） | AH42: WebSAMエージェントをインストールすることで監視する
D45: ■システム構成
E46: SCB、POM、POMDBの監視機能のシステム構成については以下の通り。
E47: POMの監視においては運用ツールを利用する。また、運用ツールの起動はIVR-DB(2号機）のJP１エージェント経由で起動する。
E48: JP1エージェントをインストール済のサーバは複数存在するが、サーバリソースに余裕があるもの、冗長化している機器を対象とし、
E49: 運用ツールの起動サーバにIVR-DB(2号機）を選定した。
E89: 5-3-1-1. プロセス監視
F90: SCBのプロセス監視する内容については、以下の通り。
F91: WebSAMエージェントをSCBにインストールすることで、プロセス監視を行う。
F93: No. | I93: 項目 | R93: 監視内容 | AG93: 説明
...

Sheet 5-4.SCB機能設計 (管理)
A1: SCM/POMサーバ基本設計書（AEP基盤編） SCB機能設計 (管理)
A3: 契約番号 | I3: - | AD3: システム名 | AM3: =目次!AM3 -> コールセンターシステム | BR3: 承認者 | BY3: 作成者 | CA3: MSYS
A4: プロジェクト名 | I4: =目次!I4 -> CC改革2.0 | AD4: サブシステム名 | AM4: =目次!AM4 -> SMCC-IVR
AD5: 作成日 | AH5: 44578 | AO5: 改定日 | AZ5: 承認日 | BK5: 版数 | BN5: 1
B9: 5-4. 管理機能
C11: 5-4-1.管理機能一覧
D12: SCBの管理機能一覧について、以下に記載する。
D13: 本機能はシステム管理者（POM保守担当者）、ユーザが利用することを前提とする。
E15: No. | H15: 項目 | AC15: 内容 | BH15: 備考
E16: 1 | H16: 業務 | L16: コールバック設定 | T16: ジョブ管理 | AC16: コールバック業務の運用条件を管理する。
E17: 2 | T17: コールバック業務 時間管理 | AC17: コールバック業務の業務時間を管理する。
E18: 3 | T18: 休日管理 | AC18: コールバック業務の休業日を管理する。 | BH18: 業務的に休日は存在しないため、使用しない機能。
E19: 4 | L19: 禁止電話番号管理 | AC19: コールバック禁止対象の電話番号を管理する。
E20: 5 | L20: インポートコールバックリスト | AC20: csvファイルから電話番号の一覧をインポートし、 CB待ちリストに登録する。
E21: 6 | L21: レポート管理 | T21: 実行済みリスト | AC21: コールバック実行済みのリストを表示する。
E22: 7 | T22: CB待ちリスト | AC22: コールバック待ちのリストを表示する。本リストより選択したデータのコールバックのキャンセルが可能。キャンセルを実行すると、該当データが実行済みリストに移る。 ※POM管理画面からのｷｬﾝｾﾙはSCBとのデータ整合性が取れなくなるので、ｷｬﾝｾﾙ不可。 | BH22: 「5-2-2.ｺﾝﾀｸﾄﾘｽﾄ連携」にてPOMに連携済みのﾃﾞｰﾀについては、本機能でｷｬﾝｾﾙ操作指示を出した後、ｼｽﾃﾑ側でPOM側のAPI（ｷｬﾝｾﾙ処理）を起動することで、POMへ連携したﾃﾞｰﾀについてもｷｬﾝｾﾙされる。ただし、既に架電処理が開始されたﾃﾞｰﾀのｷｬﾝｾﾙはできない。また、再架電となったｺｰﾙﾊﾞｯｸについては、POMからのデータ受け渡しがあるため、最短20分以上不可となる時間帯がある。
E23: 8 | T23: サマリーレポート | AC23: 月／日／時間帯ごとのコールバック件数の内訳を表示。
E24: 9 | H24: 保守 | L24: ユーザ管理 | AC24: 本管理ツールを使用するためのユーザー及びSmartCB サービス（API）アクセス用のユーザーを管理する。
E25: 10 | L25: システム管理 | AC25: 各種システムデータの設定、管理を行う。
B30: 5-4-2.画面
D31: SCB管理画面の仕様については、「06_基本設計書_SmartCB-管理画面」参照。
B34: 5-4-3.帳票
D35: SCBの帳票については、「05_基本設計書_SmartCB-帳票」参照。

Sheet 6-1～6-2.POM機能設計（全体概要・業務）
A1: SCM/POMサーバ基本設計書（AEP基盤編） POM機能設計
A3: 契約番号 | I3: - | AD3: システム名 | AM3: =目次!AM3 -> コールセンターシステム | BR3: 承認者 | BY3: 作成者 | CA3: MSYS
A4: プロジェクト名 | I4: =目次!I4 -> CC改革2.0 | AD4: サブシステム名 | AM4: =目次!AM4 -> SMCC-IVR
AD5: 作成日 | AH5: 44578 | AO5: 改定日 | AZ5: 承認日 | BK5: 版数 | BN5: 1
B9: 6.POM機能設計
C10: POMの機能設計については以下の通り。
C12: 6-1.全体概要
E13: POM機能のシステム全体概要については以下のとおり。
D52: [表 6-1-2 機能概要]
D53: No. | G53: 項目 | S53: 内容
D54: 1 | G54: 業務 | S54: コンタクトリスト登録、IVRフローへの顧客情報連携など、業務機能を提供する。 また、コンタクトリストに対して架電した結果をSCBへ連携する。
D55: 2 | G55: メンテナンス | S55: 監視（プロセス、サーバリソース等）、ログローテーションなどのSCBサーバに関するメンテナンス機能を提供する。
D56: 3 | G56: 管理 | S56: キャンペーン、コンタクトリスト等の管理機能を提供する。POM管理機能はブラウザを介してアクセスする。 また、本機能はシステム管理者（POM保守担当者）が利用し、SCB側のデータとの不整合を防ぐため、ユーザは本機能の利用を禁止することを前提とする。
C91: 6-2.業務機能概要
D92: POMの業務機能について、以下記載する。
E94: No. | H94: 項目 | Y94: 内容 | BN94: 備考
E95: 1 | H95: 業務 | M95: ｺﾝﾀｸﾄﾘｽﾄ連携 | Y95: コンタクトリスト（架電対象となる顧客情報）を登録するAPIを提供する。 | BN95: 機能詳細は6-2-1参照
E96: 2 | M96: POM情報連携 | Y96: POMの登録済みデータ（コンタクトリスト等）を連携するAPIを提供する。 | BN96: 機能詳細は6-2-2参照
E97: 3 | M97: 架電 | Y97: 登録済みのコンタクトリストを対象に架電する。架電する際はシステム管理者が登録したキャンペーン定義（発信可能時間帯、DNCリスト等）に則して架電し、架電した結果をコンタクトリストに反映する。 | BN97: 機能詳細は6-2-3参照
E98: 4 | M98: 架電結果連携 | Y98: コンタクトリストに登録済みの架電結果をSCBへ連携し、コールバックリストへ反映する。 | BN98: 機能詳細は6-2-4参照
D101: 6-2-1.ｺﾝﾀｸﾄﾘｽﾄ連携
E102: SCBから本APIを起動することにより、POMへコンタクトリスト（架電対象となる顧客情報）を登録する。
E103: 機能の詳細については、「5-2-2.ｺﾝﾀｸﾄﾘｽﾄ連携」参照。
D124: 6-2-2.POM情報連携
E126: POM情報連携について、APIはいくつか提供されているが、本項ではPOMに登録済みのコンタクトリスト連携を例に記載する。
E127: WAS上に配置された実行中のIVR着信フローから本APIを起動することによりデータを取得する。
E129: ■前提条件
F131: ① | G131: コンタクトリストの登録状態
G132: SCBよりPOMへコールバック情報が連携されることにより、POMへコンタクトリストが登録済である。
F134: ② | G134: コンタクトリスト取得方法
G135: Avaya OrchestrationDesigner（OD）のプラグインを利用し、IVR着信フローにコンタクト情報を取得処理を組み込んでおくこと。
G136: ※プラグイン（PDC）の種類はPOM用のものを利用する。
G137: ・使用するプラグイン：Get Contact Info
G138: ・事前準備
H139: WASからPOMへリクエストするためにWAS側に証明書のインポート（EPM、POM、axis2）が必要となる。
E141: ■処理イメージ
E157: 具体的な処理内容を以下に示す
F158: ① | G158: 顧客情報取得ﾘｸｴｽﾄ
G159: IVR着信フローよりPOMのODを利用して顧客情報の取得リクエストが行われる。
F161: ② | G161: コンタクトリスト取得
...

Sheet 6-3.POM機能設計 (ﾒﾝﾃ)
A1: SCM/POMサーバ基本設計書（AEP基盤編） POM機能設計
A3: 契約番号 | I3: - | AD3: システム名 | AM3: =目次!AM3 -> コールセンターシステム | BR3: 承認者 | BY3: 作成者 | CA3: MSYS
A4: プロジェクト名 | I4: =目次!I4 -> CC改革2.0 | AD4: サブシステム名 | AM4: =目次!AM4 -> SMCC-IVR
AD5: 作成日 | AH5: 44578 | AO5: 改定日 | AS5: 45432 | AZ5: 承認日 | BK5: 版数 | BN5: 1.4
B9: 6-3.メンテナンス機能概要
C11: メンテナンス機能について、以下記載する。
E13: No. | H13: 項目 | AI13: 内容 | BN13: 備考
E14: 1 | H14: メンテナンス | N14: 監視 ※1 | X14: プロセス監視 | AI14: プロセスの正常起動を定期的に監視する | BN14: 機能詳細は6-3-1-1参照
X15: アプリケーション監視 | AI15: アプリケーション正常動作を定期的に監視する | BN15: 機能詳細は6-3-1-2参照
X16: リソース監視 | AI16: CPU、メモリ、ディスク利用率を定期的に監視する | BN16: 機能詳細は6-3-1-3参照
X17: 死活監視 | AI17: 死活を定期的に監視する | BN17: 機能詳細は6-3-1-4参照
E18: 2 | N18: 定期リブート | AI18: POM（EPM、MPP、POM）のサーバリブートを定期的に行う | BN18: 機能詳細は6-3-2参照
E19: 3 | N19: DBクリア | AI19: 不要になったPOM-DB内のデータを定期的に削除する | BN19: 機能詳細は6-3-3参照
E20: 4 | N20: ログローテーション | AI20: 時間の経過とともに容量が増加する増加率が高いログ等のデータファイルについては、ディスク容量の圧迫を回避するために、データファイル削除を定期的に行う | BN20: 機能詳細は6-3-4参照
E21: 5 | N21: バックアップ | AI21: システム（OSレイヤー）をバックアップする | BN21: 機能詳細は6-3-5参照
G22: 6 | N22: backupサーバ個別ﾛｸﾞ連携 | AI22: 定義ファイルで指定したログをbackup/syslogサーバへ退避する | BN22: 機能詳細は別紙「10_基本設計書_backupサーバ個別ログ連携」を参照
G23: 7 | N23: POMサービス起動状態チェック | AI23: POMサービスの起動状態をチェックし、サービスダウンしていた場合にPOMサービスとPOMキャンペーンの再起動を行う。 | BN23: 機能詳細は別紙「11_基本設計書_POMサービス起動状態チェック」を参照
G24: 8 | N24: POMキャッシュサービス起動状態チェック | AI24: POMキャッシュサービスの起動状態をチェックし、サービスダウンしていた場合にPOMキャッシュサービスの起動を行う。 | BN24: 機能詳細は別紙「12_基本設計書_POMキャッシュサービス起動状態チェック」を参照
E25: 9 | N25: 処理実績収集 | AI25: ＣＰＵ/DISK使用率など、ハードウェアリソースの使用量を収集する | BN25: 機能詳細は6-3-6参照
E26: 10 | N26: ジョブスケジュール | AI26: 策定されたシステム稼動スケジュールおよびシステムメンテナンススケジュールに沿って各ジョブが起動、実行されるようにスケジュールを設定する | BN26: 機能詳細は6-3-7参照
E27: ※1 HW監視については、JRI様設計の範囲であることから記載の対象外とする。
C30: 6-3-1. 監視機能
E31: POMに関する監視機能について、以下に記載する。
E32: 監視機能の全体概要については「5-3-1. 監視機能」参照。
E33: 監視スケジュールについては、「6-3-6. ジョブスケジュール」参照。
E35: 6-3-1-1. プロセス監視
F36: プロセス監視する内容については、以下の通り。
F37: WebSAM代替ﾂｰﾙ（運用ﾂｰﾙ）をPOMにデプロイすることで、プロセス監視を行う。
F39: No. | I39: 項目 | R39: 監視内容 | AJ39: プロセスの説明
F40: 1 | I40: POMプロセス監視 | R40: POM Cacheプロセスの死活確認 | AJ40: Operational Databaseをインメモリで構築し、データをキャッシュすることで処理の高速化を担う。 フィルターされたレコードもこのプロセスにより、メモリー上にキャッシュされる。
F41: 2 | R41: zookeeperプロセスの死活確認 | AJ41: Supervisor Dashboardやサブスクライブしたリアルタイム・アプリケーションにPOMのリアルタイムデータを配信する。
F42: 3 | R42: kafkaプロセスの死活確認
F43: 4 | R43: POM ActiveMQプロセスの死活確認 | AJ43: POMコンポーネント間の通信を制御を行う。
F44: 5 | R44: Agent Managerプロセスの死活確認 | AJ44: エージェントの操作を管理を行う。すべての音声ベースのキャンペーンへのライセンスの配分も役割も担う。
F45: 6 | R45: Campaign Managerプロセスの死活確認 | AJ45: ストラテジーに従い発呼する。 今回は該当しないが、EメールやSMSを送信する。
F46: 7 | R46: Campaign Directorプロセスの死活確認 | AJ46: キャンペーンの起動やコンタクトリストのインポート、クリアを行う。
F47: 8 | R47: Rule Engineプロセスの死活確認 | AJ47: ルールに従い発信を制限する。
F48: 9 | R48: POM Dashboardプロセスの死活確認 | AJ48: スーパーバイザ・ダッシュボードでリアルタイム監視やキャンペーンやエージェントに対する操作が行えるようにするためのプロセス。
F56: No. | I56: 項目 | R56: 監視内容 | AJ56: プロセスの説明
F57: 10 | I57: EPMプロセス監視 | R57: httpdプロセスの死活確認 | AJ57: EPMのWebインタフェースを提供する。
...

Sheet 6-4.POM機能設計 (管理)
A1: SCM/POMサーバ基本設計書（AEP基盤編） POM機能設計 (管理)
A3: 契約番号 | I3: - | AD3: システム名 | AM3: =目次!AM3 -> コールセンターシステム | BR3: 承認者 | BY3: 作成者 | CA3: MSYS
A4: プロジェクト名 | I4: =目次!I4 -> CC改革2.0 | AD4: サブシステム名 | AM4: =目次!AM4 -> SMCC-IVR
AD5: 作成日 | AH5: 44578 | AO5: 改定日 | AZ5: 承認日 | BK5: 版数 | BN5: 1
B9: 6-4. 管理機能
C11: 6-4-1.管理機能一覧
D12: POMの管理機能一覧について、以下に記載する。
D13: 本機能はシステム管理者（POM保守担当者）が利用する。
D14: また、SCB側のデータとの不整合を防ぐため、ユーザは利用を禁止することを前提とする。
E16: No. | H16: 項目 | AI16: 内容 | BN16: 備考
E17: 1 | H17: 保守 | N17: キャンペーン | V17: キャンペーンマネージャ | AI17: キャンペーンの作成、編集、削除、およびキャンペーンの実行を行う。 また、使用するコンタクトリスト、キャンペーン戦略をキャンペーンと紐付ける。
E18: 2 | V18: キャンペーン属性の管理 | AI18: キャンペーン属性の追加、変更、削除を行う。 | BN18: 本案件では設定不要の項目 （キャンペーン属性は使用しない）
E19: 3 | V19: 完了コードの管理 | AI19: 完了コードの作成、変更、削除を行う。顧客への発信の結果が完了コードにて示される。事前定義済みの標準完了コードとは別にコードを追加する場合は本機能で作成する。 | BN19: 本案件では設定不要の項目 （標準のコードのみ使用）
E20: 4 | V20: キャンペーン戦略の管理 | AI20: キャンペーン戦略の作成、変更、削除を行う。発信のルール、種類および、動作の設定する。
E21: 5 | V21: ルールエディタの管理 | AI21: ルールエディタの作成、変更、削除を行う。発信の回数や特定の完了コードなどで、顧客への発信を制限する。
E22: 6 | V22: コールバックマネージャ | AI22: コールバック一覧の確認および、変更を行う。POMにおいてのコールバックは、エージェントベースのキャンペーンにて、発信先顧客の応答がないときや、コールバックをリクエストされたときなどに設定する。 | BN22: 本案件では設定不要の項目
E23: 7 | V23: フィルタテンプレートの管理 | AI23: フィルタテンプレートの作成、変更、削除を行う。 コンタクトリストにフィルタ（選択）をかけることが可能。 | BN23: 本案件では設定不要の項目
E27: No. | H27: 項目 | AI27: 内容 | BN27: 備考
E28: 8 | H28: 保守 | N28: コンタクト | V28: コンタクトリストの管理 | AI28: コンタクトリストの作成、編集、削除を行う。
E29: 9 | V29: 属性の管理 | AI29: 属性の作成、変更、削除を行う。 顧客情報の属性（項目）について、事前定義済みの標準属性とは別に、必要な属性を定義する。
E30: 10 | V30: DNCリストの管理 | AI30: DNCリストの追加、削除、編集を行う。 DNCリストに載せた顧客への発信は制限される。 | BN30: 本案件では設定不要の項目
E31: 11 | V31: DNCグループの管理 | AI31: DNCグループの追加、削除、編集を行う。 複数のDNCリストを1つの DNCグループに割り当てることが可能。 | BN31: 本案件では設定不要の項目
E32: 12 | V32: ファイルスプリッタの管理 | AI32: ファイルスプリッタの追加、変更、削除を行う。 フィルタテンプレートを使用して定義された分割基準に基づいてコンタクトリストの分割が可能。
E33: 13 | N33: エージェント | V33: エージェントアドレス帳の管理 | AI33: エージェントアドレス帳の追加、削除、編集を行う。 POMクライアントに表示させたいアドレスの追加を行う。 | BN33: 本案件では設定不要の項目
E34: 14 | V34: エージェントスクリプトの管理 | AI34: エージェントスクリプトの追加、削除、編集を行う。 POMクライアントに表示させたいスクリプトを定義する。 | BN34: 本案件では設定不要の項目
E35: 15 | V35: エージェント属性の管理 | AI35: エージェント属性の追加、削除、編集を行う。 | BN35: 本案件では設定不要の項目
E36: 16 | V36: エージェント設定 | AI36: POMエージェントの追加または削除を行う。 | BN36: 本案件では設定不要の項目
E37: 17 | V37: エージェントグループの管理 | AI37: エージェントグループの作成、編集、および削除を行う。 | BN37: 本案件では設定不要の項目
E38: 18 | N38: スーパーバイザ | V38: エージェントグループ割り当て | AI38: POMユーザ（スーパーバイザ）に対し、エージェントグループを割り当てる。 | BN38: 本案件では設定不要の項目
E44: No. | H44: 項目 | AI44: 内容 | BN44: 備考
E45: 19 | H45: 保守 | N45: 各種設定 | V45: POMサーバー | AI45: POMサーバーの作成、編集、及び削除を行う。 また、POMサーバーの設定、管理を行う。
E46: 20 | V46: 信頼できる POM 証明書の 管理 | AI46: 各種証明書のインポート、取得、及び削除を行う。 | BN46: 「【CC共通化】詳細設計書_インフラ_SMCC(本番環境編)_POM(アウトバウンド編)_v1.0」を参照。
E47: 21 | V47: POM ゾーン設定の管理 | AI47: ゾーン（テナント）に割り当てるPOMサーバーを管理する。 初期では、’デフォルト’ゾーンのみが存在し、作成したPOMサーバーは’デフォルト’ゾーンに割り当てられる。 | BN47: 本案件では設定不要の項目
E48: 22 | V48: POM ライセンスの管理 | AI48: POMライセンスの管理を行う。
E49: 23 | V49: グローバル設定の管理 | AI49: POM上で共通となる各種設定を行う。
E50: 24 | V50: 削除スケジュール設定 | AI50: キャンペーンデータ（レポート）等、各種データの削除スケジュールの設定を行う。
E51: 25 | H51: 業務 | V51: 電話番号形式設定 | AI51: 発信を制限する電話番号形式の設定を行う。
E52: 26 | V52: 発信可能時間帯の設定 | AI52: 発信可能な時間帯の設定を行う。
E53: 27 | V53: CMS、スキル設定 | AI53: CMS設定、及びPOMで使用するスキルを設定する。
E54: 28 | N54: POMモニター | AI54: キャンペーンの停止、及び一時停止、再開を行う。
...

Sheet 7-1～7-2.POMDB機能設計 (全体概要・ﾒﾝﾃ）
A1: SCM/POMサーバ基本設計書（AEP基盤編） DB機能設計
A3: 契約番号 | I3: - | AD3: システム名 | AM3: コールセンターシステム | BR3: 承認者 | BY3: 作成者 | CA3: MSYS
A4: プロジェクト名 | I4: CC改革2.0 | AD4: サブシステム名 | AM4: SMCC-IVR
AD5: 作成日 | AH5: 44578 | AO5: 改定日 | AZ5: 承認日 | BK5: 版数 | BN5: 1
B9: 7.POMDB機能設計
C11: 7-1.全体概要
E12: 全体概要については以下の通り。
B45: 7-2.メンテナンス機能概要
C47: メンテナンス機能について、以下に記載する。
E49: No. | H49: 項目 | AI49: 内容 | BN49: 備考
E50: 1 | H50: メンテナンス | N50: 監視 ※1 | X50: プロセス監視 | AI50: Oracleプロセスの正常起動を定期的に監視する | BN50: 機能詳細は7-2-1-1参照
X51: アプリケーション監視 | AI51: Oracle実行ログを定期的に監視する | BN51: 機能詳細は7-2-1-2参照
X52: リソース監視 | AI52: CPU、メモリ、ディスク利用率、DB使用率（表領域）を定期的に監視する | BN52: 機能詳細は7-2-1-3参照
X53: 死活監視 | AI53: 死活を定期的に監視する | BN53: 機能詳細は7-2-1-4参照
E54: 2 | N54: 定期リブート | AI54: POMDBサーバリブートを定期的に行う | BN54: 機能詳細は7-2-2参照
E55: 3 | N55: DBクリア | AI55: 不要になったSCB-DB及び、POM-DB内のデータを定期的に削除する | BN55: 機能詳細は7-2-3参照
E56: 4 | N56: ログローテーション | AI56: 時間の経過とともに容量が増加する増加率が高いログ等のデータファイルについては、ディスク容量の圧迫を回避するために、データファイル削除を定期的に行う | BN56: 機能詳細は7-2-4参照
E57: 5 | N57: バックアップ | AI57: システム（OSレイヤー）、及び、業務データ（SCB-DB、POM-DBのデータ）をバックアップする | BN57: 機能詳細は7-2-5参照
E58: 6 | N58: 統計情報の取得 | AI58: Oracleにおいて、統計情報を定期的に取得し、更新を行う。 | BN58: 機能詳細は7-2-6参照
E59: 7 | N59: 処理実績収集 | AI59: ＣＰＵ/DISK使用率など、ハードウェアリソースの使用量を収集する | BN59: 機能詳細は7-2-7参照
E60: 8 | N60: ジョブスケジュール | AI60: 策定されたシステム稼動スケジュールおよびシステムメンテナンススケジュールに沿って各ジョブが起動、実行されるようにスケジュールを設定する | BN60: 機能詳細は7-2-8参照
E62: ※1 HW監視については、JRI様設計の範囲であることから記載の対象外とする。
D66: 7-2-1. 監視機能
E68: 監視機能の全体概要については「5-3-1. 監視機能」参照。
E70: 7-2-1-1. プロセス監視
F71: プロセス監視する内容については、以下の通り。
F72: WebSAMエージェントをPOMDBにインストールすることで、プロセス監視を行う。
F74: No. | I74: 項目 | R74: 監視内容 | AJ74: プロセスの説明
F75: 1 | I75: Oracle プロセス監視 | R75: ora_pmonプロセスの死活確認 | AJ75: 他のバックグラウンド・プロセスを監視し、サーバー・プロセスまたはディスパッチャ・プロセスが異常終了した場合にプロセスのリカバリを実行するプロセスモニター。
F76: 2 | R76: ora_smonプロセスの死活確認 | AJ76: 重要なタスク(インスタンス・リカバリ、無効になったトランザクションのリカバリなど)およびメンテナンス・タスク(一時領域の再利用、データ・ディクショナリのクリーンアップ、UNDO表領域の管理など)を実行するシステムモニター。
F77: 3 | R77: tnslsnrプロセスの死活確認 | AJ77: クライアントからDatabaseへの接続依頼がきた時にDBサーバに接続要求を引き渡すプロセス。
E80: 7-2-1-2. アプリケーション監視
F81: アプリケーション監視する内容については、以下の通り。
F82: WebSAMエージェントをPOMDBにインストールすることで、アプリケーション監視を行う。
F84: No. | H84: 項目 | N84: 監視内容 | AA84: 監視対象ログファイル | AN84: 出力先 | BA84: ログ出力内容
G85: 1 | H85: Oracle ログ監視 | N85: Oracle関連のログファイルにエラーが出力されているかを監視します。 | AA85: alert_*.log | AN85: /opt/oracle/diag/rdbms/<InstanceName>/<InstanceName>/trace | BA85: データベースで発生したエラー情報が出力される。
E87: 7-2-1-3. リソース監視
F88: リソース監視する対象項目については、「運用基本設計書_IVR_12_システム監視方式 12-5. 運用監視項目 (2) 閾値監視」参照。
F89: WebSAMエージェントをPOMDBにインストールすることで、リソース監視を行う。
E93: 7-2-1-4. 死活監視
...

Sheet 参考_ログ
A1: ログ管理方式設計書 運用管理体制
A3: 契約番号 | AD3: システム名 | AM3: コールセンターシステム | BR3: 承認者 | BY3: 作成者 | CA3: MSYS
A4: プロジェクト名 | I4: コンタクトセンター共通化 | AD4: サブシステム名 | AM4: IVR
AD5: 作成日 | AH5: 43546 | AO5: 改定日 | AZ5: 承認日 | BK5: 版数
B8: 7. ログ管理実現方式
C10: 7-1. ログローテーション
D12: 7-1-1. 方針
E14: 同一ログファイルにメッセージを出力し続ける場合、日次でログをローテーションする。
E15: ローテーションをオンライン後等のログ出力静止点のタイミングで実施するといったように、ログ単位でタイミングを指定できるようにする。
E16: ログローテーション前後でアプリケーションを停止する等の処理が必要な場合には、ジョブ実行にて実現する。
E17: なお、製品ログ等で、製品機能によりローテーションされる場合には、本機能によるローテーションは行わない。
D19: 7-1-2. ローテーション方式
E21: ローテーションされたログファイルの名前は世代が判別できることが望ましい。以下の例を推奨する。
E22: <ログファイル名>.yyyymmdd
E24: syslog.logを例にログローテーション方式を以下に示す。
A43: 図 9-1 ログローテーション方式
E45: ① JP1にスケジューリングしたジョブにより、各サーバでログローテーション機能が実行され、アクティブログに対してログローテーションを行う。
G46: ログローテーションの際、ログファイル名に日付を追加する。
E47: ② ログローテーションが行われた直後に、新しいログファイルを作成する。
C49: 7-2. ログ管理
D51: 7-2-1. 方針
E53: ログは監査およびインシデント発生時の過去ログ解析等のため、長期保管しておく必要がある。
E54: ただし、一定期間経過したログは参照する可能性が低くなるため、サーバ上からは削除する。
E55: 保管期間の方針について、以下に示す。
A57: 表 9-1 ログ保管期間方針
L58: 項番 | O58: ログ種別 | AF58: サーバ内部保管期間 | AS58: 外部保管期間 | BG58: 目的
L61: 1 | O61: セキュリティ監査ログ | AF61: 6ヵ月 | AS61: 1年6ヵ月 | BG61: ・SMCC情報システムセキュリティ管理規定より、サーバ保管終了から最低１年以上の保存期間とする ・セキュリティインシデント発覚時の追跡、および監査のため
L67: 2 | O67: セキュリティ監査ログ以外 （アプリケーションログ、製品ログ等） | AF67: 6ヵ月 （ただしログサイズが大きい場合、ディスク圧迫を避けるため保存期間を短縮する） | AS67: 1年6ヵ月 | BG67: ・故障解析時の過去ログ参照のため
D73: 7-2-2. ログ外部保管（バックアップ）方式
E75: サーバ上の当日分ログを特定ディレクトリに収集し、ArcServer製品あるいは個別収集プログラムによってBackup/Sylogサーバーへ外部保管を実施する。
E77: 各サーバで以下の処理を日次でスケジューリングする。
E78: ① 収集日当日のログを収集対象に、workディレクトリにコピーする。
E79: ② workディレクトリに収集したログ全てを対象に1つのファイルに圧縮する。
E80: ③ workディレクトリのログは全て削除する。
E81: ④ バックアップ製品であるArcServe製品を用いて、backupディレクトリの圧縮ログをバックアップする。外部保管期間はバックアップ製品機能あるいは個別アーカイブ機能で設定する。
E82: ⑤ 一定期間経過した圧縮ログを削除する。
D84: 7-2-3. ログ内部保管（削除・圧縮）方式
E86: 各サーバ内部に保管されたログに対し、日次でスケジューリングされたログ削除機能により、設定ファイルに記載した内部保管期間を超過したログファイルを削除する。
E87: システム日付とログファイルの作成日付を比較する事で、保管期間の超過を確認する。
E89: ログ内部保管によるディスク圧迫を回避するため、一定期間経過したログを圧縮する機能を設ける。

Sheet 【カメラ】監視概要
C3: [図 5-3-1 監視機能システム全体概要]

Sheet 【カメラ】受付可能時間枠
B2: ■処理イメージ
B3: 例) 2022/3/1の場合
Y34: ■ 折電予約の受付可能な時間枠（受付上限数10の場合）
Y35: No. | Z35: 受付時間枠 | AC35: 受付上限数 | AD35: 受付数
Y36: 1 | Z36: 44621 | AA36: 0.375 | AB36: 0.41666667 | AC36: 10 | AD36: 10 | AE36: →空きなし
Y37: 2 | Z37: 44621 | AA37: 0.41666667 | AB37: 0.45833333 | AC37: 10 | AD37: 10 | AE37: →空きなし
Y38: 3 | Z38: 44621 | AA38: 0.45833333 | AB38: 0.5 | AC38: 10 | AD38: 8 | AE38: ←空きあり（受付上限数＞受付数）
Y39: 4 | Z39: 44621 | AA39: 0.5 | AB39: 0.54166667 | AC39: 10 | AD39: 5 | AE39: ←空きあり（受付上限数＞受付数）
Y40: 5 | Z40: 44621 | AA40: ・・ | AB40: ・・ | AC40: ・・ | AD40: ・・

Sheet 【カメラ】予約登録
C2: ■処理イメージ
O26: ■ 折電予約情報 登録後のイメージ
O27: 登録後のDB状態をイメージできるよう主要な項目のみ記載する。
O28: 折電予約時の発信者番号 | P28: 架電先の電話番号 | Q28: 折電希望日時 | R28: 即時フラグ | S28: ｶｽﾀﾑﾌｨｰﾙﾄﾞ1 | T28: ｶｽﾀﾑﾌｨｰﾙﾄﾞ2 | U28: ｶｽﾀﾑﾌｨｰﾙﾄﾞ3 | W28: jobId | X28: ジョブID *管理画面の「ジョブ」で確認可能 *API - GET: /job/dnis/{dnis} のレスポンスbodyに含まれる「id」
S29: 選択用件 ※1 | T29: 会員番号 ※1 | U29: 本人確認情報 ※1 | W29: ani | X29: 折電予約時の発信者番号
O30: 09011111111 | P30: 08033333333 | Q30: 44621.475 | R30: true | S30: 紛失盗難 | T30: 123412341234 | U30: 確認済み | W30: callbackTel | X30: 架電先の電話番号
O31: 09022222222 | P31: 08044444444 | Q31: 44621.485 | R31: false | S31: 利用不可 | T31: 678967896789 | U31: 未確認 | W31: preferredDate | X31: 折電希望日時 フォーマット： "YYYY-MM-DD hh:mm:ss" *即時指定の場合は""を設定
O32: ・・ | P32: ・・ | Q32: ・・ | R32: ・・ | S32: ・・ | T32: ・・ | U32: ・・ | W32: immediateFlag | X32: 即時フラグ true:即時指定, false:日時指定
O33: ※1 ｶｽﾀﾑﾌｨｰﾙﾄﾞは想定される設定項目（上記例では3項目を表示しているが、計5項目存在する） | W33: registrationSourceId | X33: 受付チャネル 0:IVRから予約, 1:Webから予約
W34: custom1 | X34: カスタムフィールド１
W35: custom2 | X35: カスタムフィールド２
W36: custom3 | X36: カスタムフィールド３
W37: custom4 | X37: カスタムフィールド４
W38: custom5 | X38: カスタムフィールド５

Sheet 【カメラ】予約種類
AE2: ■ 架電ﾘｽﾄ抽出のイメージ
AE3: <SCB定義値>
AF4: リトライ回数
AF5: ２
AE7: <SCB-DB>
AF8: ステータス | AG8: 架電回数
AF9: 待ち | AG9: 0 | AH9: 初回架電
AF10: 待ち | AG10: 0 | AH10: 初回架電
AF11: 待ち | AG11: 1 | AH11: 再架電(POMから架電結果連携後のデータ）
AF12: 完了 | AG12: 2
AF13: 完了 | AG13: 1

Sheet 8.セキュリティ設計
A1: SCB/POMサーバ基本設計書（AEP基盤編） セキュリティ設計
A3: 契約番号 | I3: - | AD3: システム名 | AM3: =目次!AM3 -> コールセンターシステム | BR3: 承認者 | BY3: 作成者 | CA3: MSYS
A4: プロジェクト名 | I4: =目次!I4 -> CC改革2.0 | AD4: サブシステム名 | AM4: =目次!AM4 -> SMCC-IVR
AD5: 作成日 | AH5: 44566 | AO5: 改定日 | AZ5: 承認日 | BK5: 版数 | BN5: 1
B9: 8.セキュリティ設計
C11: 8-1.ID設計（ユーザ管理）
F13: 本システムのMW（SW）で使用する各ユーザのID設計を記載する。
E15: (1) SCB
F16: SCBにアクセスするためのユーザーIDを設定する。
F17: 各ユーザーにて権限を持っている項目のみ操作可能。
F19: ログイン先 | L19: プロダクト | R19: 利用用途 | X19: 権限 | AH19: ID作成方法（※1） | AU19: PW変更ルール（※2） | BE19: 備考
F20: SCB | L20: SCB | R20: 業務 | X20: グループ管理者 | AH20: SCB管理ツール上より | AU20: 有 | BE20: ログインユーザー が属する グループ に対して、 「システム管理」以外のメニューの操作が可能
F21: 管理画面 | X21: （ADMIN） | AH21: 作成
X25: レポートユーザー | AH25: SCB管理ツール上より 作成 | AU25: 有 | BE25: ログインユーザー が属する グループ に対して、
X26: （REPORT） | BE26: 「レポート管理」 の操作が可能
R28: 開発/保守 | X28: システム管理者 | AH28: 初期インプリ済み | AU28: 無 | BE28: 全てのグループ に対して、
X29: （SYSTEM） | BE29: 全メニューの操作が可能
F33: (※1) | I33: SCBにおいて、ユーザIDには、半角英数字、最大20文字まで指定可能。
F34: (※2) | I34: 保守開発で利用するIDはルール適用外のためPW変更ルール適用外。それ以外は、JRI様のルールに準拠することとする。
I35: また、SCBにおいて、ユーザのパスワードポリシー設定、及び、パスワードの有効期限ポリシー設定機能は提供されていないが、
I36: （パスワードに設定できる値の条件の指定、及びパスワード強制更新時期の設定は行えない）
I37: 運用において、パスワードは12桁以上、アルファベット大文字小文字、数字、記号の組み合わせとする制約に準拠することとする。
I38: なお、製品の標準の制約ではパスワードに記号を使用することが不可であったため、パスワードに使用可能な文字について、本案件用に以下改修を行う。（Avaya社対応）
J39: ・ | K39: 改修前：パスワードには、半角英数字、6文字以上、最大20文字まで入力可能。（大文字・小文字を区別）
J40: ・ | K40: 改修後：パスワードには、半角英数字、記号、6文字以上、最大20文字まで入力可能。（大文字・小文字を区別）
E49: (2) POM
F51: POMは製品仕様により、権限と役割をEPM管理画面にて定義する仕様であるため、固定ユーザはいない。
F52: EPMも同様、権限と役割をEPM管理画面にて定義する仕様であるが初期インプリ済みのユーザが１ユーザ存在する。
F53: 各ユーザーにて権限を持っている項目のみ操作可能。
F54: ログイン先 | L54: プロダクト | R54: 利用用途 | X54: 権限 | AH54: ID作成方法 | AU54: PW変更ルール（※2） | BE54: 備考
F55: EPM | L55: EPM | R55: 業務 | X55: 業務では利用しない
F56: 管理画面 | R56: 開発/保守 | X56: 管理者 | AH56: EPM管理画面上よりユーザID別に権限を設定する | AU56: 無 | BE56: EPM管理画面の全メニューが操作が可能
X58: 監査者 | BE58: 監査ログに関するメニューの操作が可能
X60: メンテナンス | BE60: メンテナンスに関するメニューの操作が可能 ※「システム管理」 のメニューおいては 各マネージャ、ソフトウエアのアップデートの 操作は不可
X65: オペレーション | BE65: オペレーションに関するメニューの操作が可能 ※「システム管理」 のメニューおいては ソフトウエアのアップデートの操作は不可
X69: Privacy Manager | BE69: アプリケーションのメニューの操作が可能
X71: レポーティング | BE71: レポートのメニューの操作が可能
X73: ユーザマネージャ | BE73: ユーザー管理のメニューの操作が可能
X75: ウェブサービス | BE75: EPM管理画面の表示のみで、操作は不可
L77: POM | R77: 業務 | X77: 業務では利用しない
...

Sheet 9.ミドルウェアキャパシティ設計
A1: SCB/POMサーバ基本設計書（AEP基盤編） ミドルウェアキャパシティ設計
A3: 契約番号 | I3: - | AD3: システム名 | AM3: =目次!AM3 -> コールセンターシステム | BR3: 承認者 | BY3: 作成者 | CA3: MSYS
A4: プロジェクト名 | I4: =目次!I4 -> CC改革2.0 | AD4: サブシステム名 | AM4: =目次!AM4 -> SMCC-IVR
AD5: 作成日 | AH5: 44557 | AO5: 改定日 | AZ5: 承認日 | BK5: 版数 | BN5: 1
B9: 9.ミドルウェアキャパシティ設計
C11: 9-1.基礎数値
E12: 本システムにおけるシステム上限数量については、「3-2.HW構成 3-2-3 (1)」参照。
C48: 9-2.ライセンス
D50: 各環境にて、SCB、POM導入に必要なライセンス数量を以下に記述する。
E53: 機器 | K53: ライセンス名称 | AL53: 数量 | AU53: 備考
AL54: 本番 | AO54: 研修 | AR54: 開発
E55: SCB | K55: SmartCB サーバーライセンス | AL55: 1 | AO55: 1 | AR55: 1 | AU55: SmartCB を使用するために必要なサーバライセンス。 SmartCBサーバー1台に本ライセンスが1つ必要。
K56: SmartCBポートライセンス | AL56: 26 | AO56: 3 | AR56: 3 | AU56: コールバックを実施する際に必要なポートライセンス。
E57: POM | K57: APOM R4 OUTBOUND PER PORT VOICE LIC:CU | AL57: 26 | AO57: 3 | AR57: 3 | AU57: POMから架電する際に必要なPOMのポートライセンス。 1ポートにつき、1ライセンス必要。 ※数量について、最大同時架電数（MPPチャネル数）を18で定義する
K58: AEP R8 PER PORT NEW APPLICATION PACKAGE LIC:CU | AL58: 26 | AO58: 3 | AR58: 3 | AU58: H. 323 接続にて架電する際に必要なEPMのポートライセンス。 1ポートにつき、1ライセンス必要。
K59: AEP R8 ZONE PORT LIC:CU | AL59: 26 | AO59: 3 | AR59: 3 | AU59: 日本時間を利用するために必要なEPMゾーンライセンス。 EPMのポート数分必要。 ※ルールなどで日本時間で架電時間の制限をかけるために必要
K60: AVAYA AURA ORCHESTRATION DESIGNER R8 LIC:DS | AL60: 1 | AO60: 1 | AR60: 1 | AU60: AAOD（IVRフロー開発ツール）を利用するために必要なライセンス。
E61: CMS | K61: RT_Socket | AL61: 2 | AR61: 2 | AU61: スキル毎のオペレータの空き状況を取得するための、CMS-Webリアルタイムレポート用ライセンス。 POMにて架電ペースを決定する際に必要となる。 内訳は、本番/研修環境は共有環境であり（同じ環境で用途が違う）、CMS（Active,Stanbyでそれぞれライセンスは1個必要）で合計2つ、開発環境も同じ考え方で合計2つとなる。 ※どちらの環境もアクティブ系、スタンバイ系のCMSに１つずつ必要
C67: 9-3.システム上限数量
D69: 本システムにおけるシステム上限数量については、「3-2.HW構成 3-2-3 (1)」参照。

Sheet 10.障害対策設計
A1: SCB/POMサーバ基本設計書（AEP基盤編） 障害対策設計
A3: 契約番号 | I3: - | AD3: システム名 | AM3: =目次!AM3 -> コールセンターシステム | BR3: 承認者 | BY3: 作成者 | CA3: MSYS
A4: プロジェクト名 | I4: =目次!I4 -> CC改革2.0 | AD4: サブシステム名 | AM4: =目次!AM4 -> SMCC-IVR
AD5: 作成日 | AH5: 44566 | AO5: 改定日 | AZ5: 承認日 | BK5: 版数 | BN5: 1
B9: 10.障害対策設計
C11: 10-1.障害対策方針
D12: 二重障害は想定せず、単一障害を想定した障害対策を基本方針とする。
C14: 10-2.障害時の影響とその対策
D15: プロダクト別に障害が発生した場合の業務影響とその対策を以下に記載する。
D17: 10-2-1 サーバ障害
CD18: 〇：影響あり、△：影響あり（条件付き）、-：影響なし
E19: No. | G19: 対象 | J19: 障害ﾊﾟﾀｰﾝ | P19: ｼｽﾃﾑ状況 | U19: 業務影響 | AV19: 復旧方法 | BM19: 復旧までの運用対処
U20: 項目 | AA20: 影響 | AD20: 内容
F21: 1 | G21: SCB | J21: 仮想基盤（OS） 障害 | P21: SCB ｻｰﾋﾞｽ停止 | U21: 折電予約 | AA21: 〇 | AD21: 折電予約が受付できない | AV21: ■SCB保守担当者 仮想基盤（OS）のバックアップ情報をリストアすることで復旧させる | BM21: ■ IVR保守担当者 ・折電予約受付時にシステムメンテナンス中アナウンスを折電予約コールフロー側で再生することで、折電予約を受け付けないようにする ■ ユーザ業務担当者 ・障害が発生前までの折電予約受付分をIVR側でデータ出力し、手架電にて運用する
U22: 架電（再架電） | AA22: △ | AD22: 障害発生前までの予約受付分について、既にPOMへ連携した受付分は架電可能であるが、その後の再架電は不可となる 障害発生後の予約受付分については、再架電を含め、架電は不可となる
U23: 管理 | AA23: 〇 | AD23: SCB管理画面を利用できない
F24: 2 | J24: ﾐﾄﾞﾙｳｪｱ ｱﾌﾟﾘｹｰｼｮﾝ 障害 | U24: 折電予約 | AA24: 〇 | AD24: 折電予約が受付できない | AV24: ■SCB保守担当者 アプリケーション、ミドルウェアの障害調査を実施し調査結果に応じた対応を行う。結果復旧が困難な場合は、正常稼働していた時点の仮想基盤（OS）のバックアップデータを、リストアする。
U25: 架電（再架電） | AA25: △ | AD25: 障害発生前までの予約受付分について、既にPOMへ連携した受付分は架電可能であるが、その後の再架電は不可となる 障害発生後の予約受付分については、再架電を含め、架電は不可となる
U26: 管理 | AA26: 〇 | AD26: SCB管理画面を利用できない
F27: 3 | G27: POM | J27: 仮想基盤（OS） 障害 | P27: POM ｻｰﾋﾞｽ停止 | U27: 折電予約 | AA27: - | AD27: 影響なし | AV27: ■POM保守担当者 仮想基盤（OS）のバックアップ情報をリストアすることで復旧させる | BM27: ■ IVR保守担当者 ・折電予約受付時にシステムメンテナンス中アナウンスを折電予約コールフロー側で再生することで、折電予約を受け付けないようにする ■ ユーザ業務担当者 ・障害が発生前までの折電予約受付分をIVR側でデータ出力し、手架電にて運用する
U28: 架電（再架電） | AA28: 〇 | AD28: 架電できない
U29: 管理 | AA29: - | AD29: 影響なし（POM管理画面を業務で利用しないため）
F30: 4 | J30: ﾐﾄﾞﾙｳｪｱ ｱﾌﾟﾘｹｰｼｮﾝ 障害 | U30: 折電予約 | AA30: - | AD30: 影響なし | AV30: ■POM保守担当者 アプリケーション、ミドルウェアの障害調査を実施し調査結果に応じた対応を行う。結果復旧が困難な場合は、正常稼働していた時点の仮想基盤（OS）のバックアップデータを、リストアする。
U31: 架電（再架電） | AA31: 〇 | AD31: 架電できない
U32: 管理 | AA32: - | AD32: 影響なし（POM管理画面を業務で利用しないため）
F33: 5 | G33: POM | J33: 仮想基盤（OS） 障害 | P33: SCB-DB POM-DB ｻｰﾋﾞｽ停止 | U33: 折電予約 | AA33: 〇 | AD33: 折電予約が受付できない | AV33: ■SCB、POM保守担当者 仮想基盤（OS）のバックアップ情報をリストアすることで復旧させる | BM33: ■ IVR保守担当者 ・折電予約受付時にシステムメンテナンス中アナウンスを折電予約コールフロー側で再生することで、折電予約を受け付けないようにする ■ ユーザ業務担当者 ・障害が発生前までの折電予約受付分をIVR側でデータ出力し、手架電にて運用する
G34: DB | U34: 架電（再架電） | AA34: △ | AD34: 障害発生前までの予約受付分について、既にPOMへ連携した受付分は架電可能であるが、その後の再架電は不可となる 障害発生後の予約受付分については、再架電を含め、架電は不可となる
U35: 管理 | AA35: 〇 | AD35: SCB管理画面を利用できない
F36: 6 | J36: ﾐﾄﾞﾙｳｪｱ ｱﾌﾟﾘｹｰｼｮﾝ 障害 | U36: 折電予約 | AA36: 〇 | AD36: 折電予約が受付できない | AV36: ■SCB、POM保守担当者 アプリケーション、ミドルウェアの障害調査を実施し調査結果に応じた対応を行う。結果復旧が困難な場合は、正常稼働していた時点の仮想基盤（OS）のバックアップデータを、リストアする。
U37: 架電（再架電） | AA37: 〇 | AD37: 障害発生前までの予約受付分について、既にPOMへ連携した受付分は架電可能であるが、その後の再架電は不可となる 障害発生後の予約受付分については、再架電を含め、架電は不可となる
U38: 管理 | AA38: 〇 | AD38: SCB管理画面を利用できない
F39: 7 | J39: 仮想基盤（OS） 障害 | P39: POM-DBインスタンス停止 | U39: 折電予約 | AA39: - | AD39: 影響なし | AV39: ■POM保守担当者 仮想基盤（OS）のバックアップ情報をリストアすることで復旧させる
U40: 架電（再架電） | AA40: 〇 | AD40: 架電できない
U41: 管理 | AA41: - | AD41: 影響なし（POM管理画面を業務で利用しないため）
F42: 8 | J42: ﾐﾄﾞﾙｳｪｱ ｱﾌﾟﾘｹｰｼｮﾝ 障害 | U42: 折電予約 | AA42: - | AD42: 影響なし | AV42: ■POM保守担当者 DBの障害調査を実施し調査結果に応じた対応を行う。結果復旧が困難な場合は、DBを再構築後、正常稼働していた時点のDBバックアップデータを、リストアする。
U43: 架電（再架電） | AA43: 〇 | AD43: 架電できない
U44: 管理 | AA44: - | AD44: 影響なし（POM管理画面を業務で利用しないため）
D48: 10-2-2 機器障害
D50: No | F50: 障害対象 | N50: 影響を受けるサーバ | AE50: 障害発生時の影響 | BD50: 障害発生時の対策
D52: 1 | F52: 本番機 | N52: SCB POM POMDB | AE52: 左記サーバが提供している機能が一律失われる ※各サーバ障害時のシステム動作、業務影響は（１）にて個別に記載した内容と同様。 | BD52: 左記サーバ（仮想機器）を全て別機器へ移動する。 ※サポート対象はVMHAのみで、vMotionはAvayaサポート対象外 ※別機器へ移動した際、MACアドレスが変わる場合は、移動後のMACアドレスでライセンス情報を払い出し、ライセンスの再登録が必要
...

Sheet 11.運用設計
A1: SCB/POMサーバ基本設計書（AEP基盤編） 運用設計
A3: 契約番号 | I3: - | AD3: システム名 | AM3: =目次!AM3 -> コールセンターシステム | BR3: 承認者 | BY3: 作成者 | CA3: MSYS
A4: プロジェクト名 | I4: =目次!I4 -> CC改革2.0 | AD4: サブシステム名 | AM4: =目次!AM4 -> SMCC-IVR
AD5: 作成日 | AH5: 44557 | AO5: 改定日 | AZ5: 承認日 | BK5: 版数 | BN5: 1
B9: 11.運用設計
D12: SMCC-IVRシステムの運用基本設計書にて記述する。

Sheet 12.ホスト名ネーミングルール
A1: SCB/POMサーバ基本設計書（AEP基盤編） ホスト名ネーミングルール
A3: 契約番号 | I3: - | AD3: システム名 | AM3: =目次!AM3 -> コールセンターシステム | BR3: 承認者 | BY3: 作成者 | CA3: MSYS
A4: プロジェクト名 | I4: =目次!I4 -> CC改革2.0 | AD4: サブシステム名 | AM4: =目次!AM4 -> SMCC-IVR
AD5: 作成日 | AH5: 44557 | AO5: 改定日 | AZ5: 承認日 | BK5: 版数 | BN5: 1
B9: 12.ホスト名ネーミングルール
D12: 【CC共通化】基本設計書_共通_別紙1_SMCC_ホスト名ネーミングルールにて記述する。

Sheet 13.バックアップサーバ設計
A1: SCB/POMサーバ基本設計書（AEP基盤編） バックアップサーバ設計
A3: 契約番号 | I3: - | AD3: システム名 | AM3: =目次!AM3 -> コールセンターシステム | BR3: 承認者 | BY3: 作成者 | CA3: MSYS
A4: プロジェクト名 | I4: =目次!I4 -> CC改革2.0 | AD4: サブシステム名 | AM4: =目次!AM4 -> SMCC-IVR
AD5: 作成日 | AH5: 44566 | AO5: 改定日 | AZ5: 承認日 | BK5: 版数 | BN5: 1
B9: 13.バックアップサーバ設計
C11: バックアップサーバ設計については、以下参照。（環境ごとに参照先が異なる）
D13: ・本番/研修環境
E14: 【CC共通化】基盤基本設計書_SMCC_IVR(本番・研修環境)
D16: ・開発環境
E17: 【CC共通化】基盤基本設計書_SMCC_IVR(開発環境)

Sheet 14.時刻同期設計
A1: SCB/POMサーバ基本設計書（AEP基盤編） 時刻同期設計
A3: 契約番号 | I3: - | AD3: システム名 | AM3: =目次!AM3 -> コールセンターシステム | BR3: 承認者 | BY3: 作成者 | CA3: MSYS
A4: プロジェクト名 | I4: =目次!I4 -> CC改革2.0 | AD4: サブシステム名 | AM4: =目次!AM4 -> SMCC-IVR
AD5: 作成日 | AH5: 44557 | AO5: 改定日 | AZ5: 承認日 | BK5: 版数 | BN5: 1
B9: 14.時刻同期設計
D11: 時刻同期設計については、「運用基本設計書_IVR_11_時刻同期運用方式」にて記述する。

Sheet 15.用語集
A1: SCB/POMサーバ基本設計書（AEP基盤編） 用語集
A3: 契約番号 | I3: - | AD3: システム名 | AM3: =目次!AM3 -> コールセンターシステム | BR3: 承認者 | BY3: 作成者 | CA3: MSYS
A4: プロジェクト名 | I4: =目次!I4 -> CC改革2.0 | AD4: サブシステム名 | AM4: =目次!AM4 -> SMCC-IVR
AD5: 作成日 | AH5: 44532 | AO5: 改定日 | AZ5: 承認日 | BK5: 版数 | BN5: 1
B9: 15.用語集
D11: 【CC共通化】基本設計書_共通_別紙2_CTI基盤_用語集（本番環境編）にて記述する。

Sheet 【カメラ】CMS接続

Sheet 【カメラ】全体概要図
B2: [図 5-1-1 SCB機能システム全体概要]
B64: [図 6-1-1 POM機能システム全体概要]
B126: [図 5-2-2.ｺﾝﾀｸﾄﾘｽﾄ連携処理イメージ]
B158: [図 6-2-2.顧客情報連携イメージ]
B179: [図 6-2-3.架電処理イメージ]
B218: [図 6-2-4.架電結果連携イメージ]
B254: [図 7-1-1 SCB機能システム全体概要]
